Workbook
Name 手部装备名: _xlfn.ANCHORARRAY(动态备表!$D$2)
Name 头部装备名: _xlfn.ANCHORARRAY(动态备表!$C$2)
Name 武器装备名: _xlfn.ANCHORARRAY(动态备表!$A$2)
Name 鞋子装备名: _xlfn.ANCHORARRAY(动态备表!$E$2)
Name 衣服装备名: _xlfn.ANCHORARRAY(动态备表!$B$2)

Sheet 伤害计算器
B1: 面板数值 | D1: 用小数点 | E1: 手动填 | K1: 腐化百分比是向上取整的值 | N1: 抄俩T血防用来算一下 | O1: 血 | P1: 防
A2: 攻击力 | B2: 法强 | C2: 防穿数值 | D2: 防穿百分比 | E2: 伤害提升 | G2: 熟练等级 | H2: 叠层特效 | K2: =0.002*B5 -> 1.24 | N2: 钓鱼6级 | O2: 2080 | P2: 131
A3: 155 | B3: 620 | C3: 0 | D3: 0 | E3: 0 | G3: 20 | H3: 吸血鬼满层 | I3: FALSE | K3: =0.002*B5+0.9 -> 2.14 | N3: 钓鱼15级单魔兔帽 | O3: 3110 | P3: 156
A4: ↑没用 | B4: 最终法强 | D4: ↑没加天赋 | E4: 最终伤害提升(+炽燃) | H4: 炽燃满层 | I4: FALSE | N4: 15级武器衣服头 | O4: 3160 | P4: 166
B5: =B3 + IF(I3, G3 + 14, 0) -> 620 | E5: =E3 + IF(I4, 0.15, 0) -> 0 | H5: 斥力弹升级 | I5: TRUE
B6: 敌人面板 | N6: 20级全装 | O6: 4110 | P6: 187
B7: 血量 | C7: 防御 | D7: 防御减少% | E7: 伤害减免 | F7: 10%上限 | G7: 熟练等级 | H7: ←能选但没用 | K7: 计算减免 | N7: 20级全装无惧感 | O7: 4110 | P7: 212
B8: 1000 | C8: 140 | D8: 0 | E8: 0 | F8: =0.1*B8 -> 100 | G8: 20 | H8: 因为敌方熟练公式没写 | J8: 诅咒(真) | K8: 4s后触发
B9: 自身血量 | C9: 血量差比 | D9: 爆发力增伤% | J9: =50+B5*0.15 -> 143
B10: 2514 | C10: =MIN(0.4, MAX(0.1, (B8-B10)/B10)) -> 0.1 | D10: =MIN(0.1, MAX(0, (B8-B10)/B10) * 0.25) -> 0 | J10: 腐化(技) | L10: 共3跳
A11: 红底的是公式格不要动了，只改绿底的就行 | J11: =B8*(0.9+0.002*B5)/100 -> 21.4 | K11: =J11*O26 -> 8.9166667 | L11: =3*K11 -> 26.75
A12: 一般直接按20级熟练度算，虽然我做了下拉列表，但是我又不想做 | J12: 伤痕(技)
J13: =10+20+B8*0.03 -> 60 | K13: =J13*O26 -> 25
A14: 所有数值向下取整 | J14: 伤口撕裂 | K14: 以触发时70%血计
J15: =50+B8*0.7*0.08 -> 106 | K15: =J15*O26 -> 44.166667
A16: 各种天赋特效我没加算只有大概数值，实际伤害一般来说只会比这个高，比如强化装置 | J16: 特效小计 | L16: 鬼火(真伤)
A17: 控制变量不换天赋的情况下无所谓 | J17: =L11+J9+K13+K15 -> 238.91667 | K17: + | L17: =熟练度级别法强加成表!M22 -> 374
J18: 斥力弹F | O18: ↓别动这列公式全用的这里
A19: 伤害减免：20熟时默认有16%技能伤害减免，与其他减伤是加算，与伤害提升也是加算 | J19: =5*(10+G3*1)+(B8*0.006) + IF(I5, 3*(10+G3*1), 0) -> 246 | M19: 计算过程
A20: 因为【爆发力】天赋有额外伤害提升，所以打肉的时候实际伤害要比这个高 | M20: 有效防御 | N20: C7*(1-D3) | O20: ←C7是防御，现在请换成C8……
A21: 木桩的伤害减免是0，所以实际打到人身上记得写0.16伤害减免哈 | M21: 最终防御 | N21: C7*(1-D7)*(1-D3)-C3
A22: 修女 | M22: 防御修正 | N22: 100/(100+C7*(1-D7)*(1-D3)-C3) | O22: =100/(100+C8*(1-D8)*(1-D3)-C3) -> 0.41666667
E23: ↓debug的时候自己改，有问题问我吧
A24: // 最终伤害就是加算法强后*O22*O24 | E24: //法强是B5 | G24: 叠层应该是(1+n*0.2)我没测过不知道对不对我不玩修女 | M24: 增减伤合算 | N24: 1+E3-E7 | O24: =1+E5-E8 -> 1
B25: 按满级技能计，多的自己填，最终伤害在上面，自己对下技能看看公式对不对（）
A26: 修女 | B26: Q | C26: W | D26: E | E26: R | F26: R2 | G26: R2带叠层 | H26: 叠层层数 | M26: 最终修正值 | O26: =O22*O24 -> 0.41666667 | P26: ←用的这个
A27: 一次 | B27: =180+B5*0.65 -> 583 | C27: =160+0.5*B5+0.1*B8 -> 570 | D27: =130+0.4*B5 -> 378 | E27: =80+0.25*B5 -> 235 | F27: =150+0.25*B5 -> 305 | G27: =F27*(1+0.2) -> 366 | H27: 1
A28: 二次/额外 | B28: =50+0.08*B5 -> 99.6 | D28: =160+0.7*B5 -> 594 | G28: =F27*(1+0.4) -> 427 | H28: 2
G29: =F27*(1+0.6) -> 488 | H29: 3
G30: =F27*(1+0.8) -> 549 | H30: 4 | I30: ←好像是对的 | M30: 爆发力追伤=(技能基础+法强)*爆发力系数*防御修正
A31: 最终伤害 | B31: 自己向下取整一下懒得写了无论何种情况都向下取整 | I31: 看白字是对的…… | M31: 【目标防御降低百分比=龙首簪那种特效】
A32: 一次 | B32: =B27*O22*O24 -> 242.91667 | C32: =C27*O22*O24 -> 237.5 | D32: =D27*O22*O24 -> 157.5 | E32: =E27*O22*O24 -> 97.916667 | F32: =F27*O22*O24 -> 127.08333 | G32: =G27*O22*O24 -> 152.5 | M32: 【防穿数值=剑齿虎那种；防穿百分比=龙鳞那种，不同】
A33: 二次 | B33: =B28*O22*O24 -> 41.5 | D33: =D28*O22*O24 -> 247.5 | G33: =G28*O22*O24 -> 177.91667 | M33: 【自身伤害提升=光辉头or炽燃等；目标伤害减免=防御熟练度、天赋等】
G34: =G29*O22*O24 -> 203.33333 | M34: 有效防御 | N34: 目标防御*(1-防穿百分比)
A35: ps.修女的装备特效我没写，这是纯技伤，特效自己拉个公式 | G35: =G30*O22*O24 -> 228.75 | M35: 最终防御 | N35: 目标防御*(1-防穿百分比)*目标防御降低百分比-防穿数值
M36: 防御修正值 | N36: 100/(100+最终防御)
A37: 体力回复我没写 | M37: 增减伤 | N37: 1+(自身伤害提升-目标伤害减免)
M38: 最终伤害修正值 | N38: 防御修正*增减伤
M39: 最终伤害 | N39: 技能伤害*最终伤害修正值
A40: 伤害计算公式
...

Sheet 装备属性计算器
B1: 我说这是配装模拟器你耳朵聋吗？
C2: 装备选择 | D2: 特效 | F2: 熟练度等级 | G2: 20
B3: 武器 | C3: 阿戈斯之眼 | D3: {=_xlfn.MAP(C3:C7, _xlfn.LAMBDA(_xlpm.x, IF(_xlpm.x="","", IF(_xlfn.XLOOKUP(_xlpm.x, 装备表!$B:$B, 装备表!$K:$K, "")="","", _xlfn.XLOOKUP(_xlpm.x, 装备表!$B:$B, 装备表!$K:$K, "") ) ) ))} -> 破裂
B4: 衣服 | C4: 私人订制 | D4: 炽燃 | F4: 天赋 | G4: 法强
B5: 头部 | C5: 先知头巾 | D5: 减疗 | F5: 凝力 | G5: 32
B6: 手部 | C6: 翡翠石板 | D6: 神速 | F6: 猎魂熊 | G6: 20
B7: 鞋子 | C7: 精灵之靴 | D7: 乘风,减疗
O8: debug用熟练度法强查表别管
B9: 最终法强 | C9: =INT(G15) -> 895 | D9: 已取整 | F9: 计算过程公式拆分(debug用 | J9: ↓角色属性栏里自己找 | O9: =_xlfn.XLOOKUP( G2, 熟练度级别法强加成表!$A:$A, 熟练度级别法强加成表!$B:$B, 0 ) -> 0.8
B10: CD | C10: {=SUM(_xlfn.XLOOKUP(C3:C7, 装备表!$B:$B, 装备表!$F:$F, 0))} -> 70 | F10: 装备法强结算 | G10: {=SUM(_xlfn.XLOOKUP(C3:C7, 装备表!$B:$B, 装备表!$C:$C, 0))} -> 440 | I10: 每级别熟练度法强 | J10: 0.041
B11: 防穿 | C11: {=SUM(_xlfn.XLOOKUP(C3:C7, 装备表!$B:$B, 装备表!$H:$H, 0))} -> 0 | F11: 天赋法强 | G11: =G5+G6 -> 52
B12: 防穿% | C12: {=SUM(_xlfn.XLOOKUP(C3:C7, 装备表!$B:$B, 装备表!$I:$I, 0))} -> 0 | F12: 法强% | G12: {=_xlfn.LET( _xlpm.equip, C3:C7, _xlpm.names, 装备表!$B:$B, _xlpm.apPct, 装备表!$D:$D, _xlpm.uniqueFlag, 装备表!$E:$E, _xlpm.normalPct, SUM( _xlfn.XLOOKUP( _xlfn._xlws.FILTER(_xlpm.equip, _xlfn.XLOOKUP(_xlpm.equip, _xlpm.names, _xlpm.uniqueFlag, "")<>"独有"), _xlpm.names, _xlpm.apPct, 0 ) ), _xlpm.uniquePct, IFERROR( MAX( _xlfn.XLOOKUP( _xlfn._xlws.FILTER(_xlpm.equip, _xlfn.XLOOKUP(_xlpm.equip, _xlpm.names, _xlpm.uniqueFlag)="独有"), _xlpm.names, _xlpm.apPct, 0 ) ), 0 ), _xlpm.normalPct + _xlpm.uniquePct )} -> 0 | H12: 已独有 | I12: 已计算独有，重复会自动取最高
F13: 熟练度法强% | G13: =G2*J10 -> 0.82
F14: 合计法强% | G14: =G12+G13 -> 0.82
F15: 最终法强 | G15: =(G10+G11)*(G14+1) -> 895.44 | H15: 向下取整

Sheet 装备表
A1: 装备类型 | B1: 名称 | C1: 法强 | D1: 法强% | E1: 法强独有 | F1: CD | G1: 防御力 | H1: 防穿 | I1: 防穿% | J1: 独有伤害增幅 | K1: 特效 | L1: 备注 | M1: 品质 | N1: 这里只有法强什么的没有别的数据什么体力暴击之类的
A2: 武器 | B2: 月水晶 | C2: 88 | F2: 10 | K2: 诅咒 | M2: 金
A3: 武器 | B3: 女帝 | C3: 93 | F3: 15 | K3: 寒波 | M3: 金 | Q3: 施工中 我实在懒得再做一次下拉选框公式
A4: 武器 | B4: 隐遁者 | C4: 70 | F4: 10 | K4: 诅咒 | M4: 紫 | Q4: 还不如直接进游戏穿上看看最终数值‘
A5: 武器 | B5: 五芒星 | C5: 68 | F5: 15 | M5: 紫
A6: 武器 | B6: 命运之轮 | C6: 66 | F6: 10 | K6: 减疗 | M6: 紫
A7: 武器 | B7: 炼狱 | C7: 112 | F7: 15 | I7: 0.1 | K7: 吸血6% | M7: 红 | P7: 配装器草稿
A8: 武器 | B8: 炼狱绯红 | C8: 100 | F8: 15 | I8: 0.07 | K8: 诅咒 | M8: 红 | Q8: 装备选择 | R8: 特效 | T8: 熟练度等级 | U8: 20
A9: 武器 | B9: 炼狱晓色 | C9: 110 | F9: 15 | I9: 0.08 | K9: 寒波 | M9: 红 | P9: 武器 | Q9: 炼狱 | R9: {=_xlfn.MAP(Q9:Q13, _xlfn.LAMBDA(_xlpm.x, IF(_xlpm.x="","", IF(_xlfn.XLOOKUP(_xlpm.x, 装备表!$B:$B, 装备表!$K:$K, "")="","", _xlfn.XLOOKUP(_xlpm.x, 装备表!$B:$B, 装备表!$K:$K, "") ) ) ))} -> 吸血6%
P10: 衣服 | Q10: 私人订制 | R10: 炽燃 | T10: 天赋 | U10: 法强
P11: 头部 | Q11: 幽灵面具 | T11: 凝力 | U11: 32
A12: 衣服 | B12: 私人订制 | C12: 125 | F12: 10 | K12: 炽燃 | L12: 0.15 | M12: 金 | P12: 手部 | Q12: 翡翠石板 | R12: 神速 | T12: 猎魂熊 | U12: 20
A13: 衣服 | B13: 神职法衣 | C13: 130 | D13: 0.25 | E13: 独有 | F13: 0 | M13: 金 | P13: 鞋子 | Q13: 精灵之靴 | R13: 乘风,减疗
A14: 衣服 | B14: 优雅礼服 | C14: 120 | F14: 20 | K14: 凝聚 | M14: 金
A15: 衣服 | B15: 血色斗篷 | C15: 122 | F15: 0 | K15: 腐化 | M15: 金 | P15: 最终法强 | Q15: =INT(U21) -> 1053 | R15: 向下取整 | T15: 计算过程公式拆分(debug用
A16: 衣服 | B16: 日轮之铠 | C16: 135 | F16: 10 | K16: 减疗 | M16: 金 | P16: CD | Q16: {=SUM(_xlfn.XLOOKUP(Q9:Q13, 装备表!$B:$B, 装备表!$F:$F, 0))} -> 65 | T16: 装备法强结算 | U16: {=SUM(_xlfn.XLOOKUP(Q9:Q13, 装备表!$B:$B, 装备表!$C:$C, 0))} -> 462
A17: 衣服 | B17: 异端审判官 | C17: 138 | F17: 15 | K17: 刽子手 | M17: 金 | P17: 防穿 | Q17: {=SUM(_xlfn.XLOOKUP(Q9:Q13, 装备表!$B:$B, 装备表!$H:$H, 0))} -> 0 | T17: 天赋法强 | U17: =U11+U12 -> 52
A18: 衣服 | B18: 比基尼 | C18: 135 | K18: 减疗 | M18: 红 | P18: 防穿% | Q18: {=SUM(_xlfn.XLOOKUP(Q9:Q13, 装备表!$B:$B, 装备表!$I:$I, 0))} -> 0.1 | T18: 法强% | U18: {=_xlfn.LET( _xlpm.equip, Q9:Q13, _xlpm.names, 装备表!$B:$B, _xlpm.apPct, 装备表!$D:$D, _xlpm.uniqueFlag, 装备表!$E:$E, _xlpm.normalPct, SUM( _xlfn.XLOOKUP( _xlfn._xlws.FILTER(_xlpm.equip, _xlfn.XLOOKUP(_xlpm.equip, _xlpm.names, _xlpm.uniqueFlag, "")<>"独有"), _xlpm.names, _xlpm.apPct, 0 ) ), _xlpm.uniquePct, IFERROR( MAX( _xlfn.XLOOKUP( _xlfn._xlws.FILTER(_xlpm.equip, _xlfn.XLOOKUP(_xlpm.equip, _xlpm.names, _xlpm.uniqueFlag)="独有"), _xlpm.names, _xlpm.apPct, 0 ) ), 0 ), _xlpm.normalPct + _xlpm.uniquePct )} -> 0.25 | V18: 有独有自动会算
A19: 衣服 | B19: 红心女王 | C19: 135 | F19: 25 | K19: 凝聚,减疗 | M19: 红 | T19: 熟练度法强% | U19: =_xlfn.XLOOKUP( U8, 熟练度级别法强加成表!$A:$A, 熟练度级别法强加成表!$B:$B, 0 ) -> 0.8
A20: 衣服 | B20: 指挥官战甲 | C20: 126 | M20: 紫 | T20: 合计法强% | U20: =U18+U19 -> 1.05
A21: 衣服 | B21: 御史衣 | C21: 112 | F21: 10 | M21: 紫 | T21: 最终法强 | U21: =(U16+U17)*(U20+1) -> 1053.7 | V21: 向下取整
A22: 衣服 | B22: 大祭司长袍 | C22: 100 | F22: 20 | M22: 紫
A23: 衣服 | B23: 白大褂 | C23: 100 | F23: 10 | M23: 紫
A24: 衣服 | B24: 主教长袍 | C24: 124 | K24: 减疗 | M24: 紫
A25: 衣服 | B25: 幽冥战甲 | C25: 100 | K25: 疾风 | M25: 紫
A27: 头部 | B27: 幽灵面具 | C27: 80 | D27: 0.25 | E27: 独有 | M27: 金
A28: 头部 | B28: 先知头巾 | C28: 80 | F28: 20 | K28: 减疗 | M28: 金
A29: 头部 | B29: 太空头盔 | C29: 60 | F29: 10 | K29: 腐化 | M29: 紫
A30: 头部 | B30: EnGrade | C30: 75 | F30: 10 | K30: 炽燃 | L30: 0.15 | M30: 金
A31: 头部 | B31: 暗影面纱 | C31: 80 | F31: 15 | J31: 0.12 | K31: 光辉 | M31: 金
A32: 头部 | B32: 昆德拉 | C32: 75 | F32: 20 | M32: 金
A33: 头部 | B33: 龙首簪 | C33: 55 | F33: 15 | I33: 0.2 | K33: 粉碎 | M33: 金
A34: 头部 | B34: 脸谱 | C34: 90 | F34: 20 | H34: 10 | K34: 减疗 | M34: 红
A35: 头部 | B35: 赛车头盔 | C35: 80 | F35: 10 | K35: 光子发射器 | M35: 金
A36: 头部 | B36: 魔女帽 | C36: 63 | F36: 10 | K36: 减疗 | M36: 紫
A37: 头部 | B37: 战队头盔 | C37: 50 | F37: 10 | K37: 腐化 | M37: 紫
A38: 头部 | B38: 帝国战盔 | C38: 78 | M38: 紫
A39: 头部 | B39: 帝国皇冠 | C39: 63 | F39: 15 | M39: 紫
A41: 手部 | B41: 翡翠石板 | C41: 85 | F41: 20 | K41: 神速 | M41: 金
A42: 手部 | B42: 龙鳞 | C42: 85 | I42: 0.15 | M42: 金
...

Sheet 动态备表
A1: 武器 | B1: 衣服 | C1: 头部 | D1: 手部 | E1: 鞋子 | G1: {=_xlfn.IFS( 装备表!M2="紫","紫 "&装备表!B2, 装备表!M2="金","金 "&装备表!B2, 装备表!M2="红","红 "&装备表!B2, TRUE, 装备表!B2 )} -> 金 月水晶
A2: {=_xlfn.LET( _xlpm.result, _xlfn._xlws.FILTER( 装备表!$B:$B, (装备表!$A:$A="武器")*(装备表!$B:$B<>""), "" ), IF(COUNTA(_xlpm.result)>0, _xlfn.VSTACK(_xlpm.result,""), _xlpm.result) )} -> 月水晶 | B2: {=_xlfn.LET( _xlpm.result, _xlfn._xlws.FILTER( 装备表!$B:$B, (装备表!$A:$A="衣服")*(装备表!$B:$B<>""), "" ), IF(COUNTA(_xlpm.result)>0, _xlfn.VSTACK(_xlpm.result,""), _xlpm.result) )} -> 私人订制 | C2: {=_xlfn.LET( _xlpm.result, _xlfn._xlws.FILTER( 装备表!$B:$B, (装备表!$A:$A="头部")*(装备表!$B:$B<>""), "" ), IF(COUNTA(_xlpm.result)>0, _xlfn.VSTACK(_xlpm.result,""), _xlpm.result) )} -> 幽灵面具 | D2: {=_xlfn.LET( _xlpm.result, _xlfn._xlws.FILTER( 装备表!$B:$B, (装备表!$A:$A="手部")*(装备表!$B:$B<>""), "" ), IF(COUNTA(_xlpm.result)>0, _xlfn.VSTACK(_xlpm.result,""), _xlpm.result) )} -> 翡翠石板 | E2: {=_xlfn.LET( _xlpm.result, _xlfn._xlws.FILTER( 装备表!$B:$B, (装备表!$A:$A="鞋子")*(装备表!$B:$B<>""), "" ), IF(COUNTA(_xlpm.result)>0, _xlfn.VSTACK(_xlpm.result,""), _xlpm.result) )} -> 风火轮
A3: 女帝 | B3: 神职法衣 | C3: 先知头巾 | D3: 龙鳞 | E3: SCV
A4: 隐遁者 | B4: 优雅礼服 | C4: 太空头盔 | D4: 极光陀螺 | E4: 赤影
A5: 五芒星 | B5: 血色斗篷 | C5: EnGrade | D5: 极光陀螺(满层) | E5: 恨天高
A6: 命运之轮 | B6: 日轮之铠 | C6: 暗影面纱 | D6: 守护之眼 | E6: 万年冰鞋
A7: 炼狱 | B7: 异端审判官 | C7: 昆德拉 | D7: 斯嘉蒂的手镯 | E7: 锋利长靴
A8: 炼狱绯红 | B8: 比基尼 | C8: 龙首簪 | D8: 廷达罗斯君主 | E8: 蔷薇轻履
A9: 炼狱晓色 | B9: 红心女王 | C9: 脸谱 | D9: 鬼灵之爪 | E9: 精灵之靴
A10: 阿戈斯之眼 | B10: 指挥官战甲 | C10: 赛车头盔 | D10: 芭蕉扇
A11: 米斯特汀 | B11: 御史衣 | C11: 魔女帽 | D11: 荷鲁斯之眼
A12: 诺斯费拉图 | B12: 大祭司长袍 | C12: 战队头盔 | D12: 超星臂章
A13: 诺斯费拉图-晓色 | B13: 白大褂 | C13: 帝国战盔 | D13: 死灵之书
B14: 主教长袍 | C14: 帝国皇冠 | D14: 巨人手套
B15: 幽冥战甲 | D15: 德罗普尼尔
D16: 廷达罗斯手环
D17: 白羽扇
D18: 邀明月

Sheet 移速
B1: 0.06 | C1: 0.035 | D1: 0.06
B2: 炽燃头 | C2: 幽灵面具 | D2: 龙首簪 | F2: 红鞋0.27 | G2: 4.09 | I2: 底数据
A3: 0.06 | B3: / | C3: 常驻4.21 | D3: 4.09 | I3: 红鞋0.27 | J3: 4.09 | K3: 精灵之靴+5%
A4: 炽燃衣 | B4: / | C4: 触发5.95 | D4: 5.93 | I4: 金鞋0.25 | J4: 4.07
A5: 1.5%*8=12% | B5: 4.09 | C5: 常驻4.21 | D5: 常驻4.09 | I5: （20级熟+等离子0.1
A6: 赛车服 | B6: 6.15 | C6: 触发6.09 | D6: 触发6.07
I7: 翡翠石板 | J7: 0.3 | K7: 3s
G9: 传说中的手测表，感觉不如配装
A10: 俞岷 20熟练度+等离子提升0.1+石板30% | G10: 常驻/吸血鬼+叠层满层
A11: 常驻/全特效触发(2级闪+风圈10%) | H11: 15%增伤 | I11: 25%法强 | L11: 圣器20级技能增幅80%，每等级+4%
A12: 4.07 | B12: 炽燃头 | C12: 幽灵面具 | D12: 龙首簪 | G12: 龙鳞 | H12: 炽燃头 | I12: 幽灵面具 | J12: 昆德拉
A13: 炽燃衣 | B13: / | C13: 4.21/5.81 | D13: 4.07/5.79 | F13: 25%法强 | G13: 神职法衣 | H13: 949/1051 | I13: 同→ | J13: 922/1024
A14: 赛车服 | B14: 4.07/6.01 | C14: 4.21/5.95 | D14: 4.07/5.93 | G14: 优雅礼服 | H14: 815/905 | I14: 902/1004 | J14: 792/882
A15: 精灵之靴+5% | G15: 火衣 | H15: 786/876 | I15: 906/1008 | J15: 795/885 | L15: 面纱/昆德拉/面具增幅都是80，CD区别/特效区别
A16: 4.09+5% | B16: 炽燃头 | C16: 幽灵面具 | D16: 龙首簪 | F16: 15%增伤 | G16: 私人订制 | H16: 792/882 | I16: 912/1014 | J16: 801/891 | L16: 炽燃头增幅75
A17: 炽燃衣 | B17: / | C17: 4.21/5.95 | D17: 4.09/5.93 | G17: ps.炽燃重复优先级头>衣 | L17: 龙首簪/太空头55
A18: 赛车服 | B18: 4.09/6.15 | C18: 4.21/6.09 | D18: 4.09/6.07 | G18: 守护之眼 | H18: 炽燃头 | I18: 幽灵面具 | J18: 昆德拉
G19: 神职法衣
G20: 优雅礼服 | L20: 优雅礼服20，火衣22，私人订制25，法衣30，最后额外根据等级+100
G21: 火衣 | H21: 861/958
G22: 私人订制 | J22: 877/974

Sheet 熟练度级别法强加成表
A1: 1 | B1: 0.04 | D1: 这个左表是俞岷的 | H1: 10 | I1: 2.5 | K1: 鬼火
A2: 2 | B2: 0.08 | D2: 其他角色要另外写 | H2: 20 | I2: 5 | K2: 等级 | L2: 60~250 | M2: 结算 | N2: ←这列有公式别动
A3: 3 | B3: 0.12 | D3: 自己看属性每级熟练度 | H3: 30 | I3: 7.5 | K3: 1 | L3: 60 | M3: =0.2*伤害计算器!B5+L3 -> 184
A4: 4 | B4: 0.16 | H4: 40 | I4: 10 | K4: 2 | L4: 70 | M4: =0.2*伤害计算器!B5+L4 -> 194
A5: 5 | B5: 0.2 | D5: PS.修女是每级4.1 | K5: 3 | L5: 80 | M5: =0.2*伤害计算器!B5+L5 -> 204
A6: 6 | B6: 0.24 | K6: 4 | L6: 90 | M6: =0.2*伤害计算器!B5+L6 -> 214
A7: 7 | B7: 0.28 | K7: 5 | L7: 100 | M7: =0.2*伤害计算器!B5+L7 -> 224
A8: 8 | B8: 0.32 | K8: 6 | L8: 110 | M8: =0.2*伤害计算器!B5+L8 -> 234
A9: 9 | B9: 0.36 | K9: 7 | L9: 120 | M9: =0.2*伤害计算器!B5+L9 -> 244
A10: 10 | B10: 0.4 | K10: 8 | L10: 130 | M10: =0.2*伤害计算器!B5+L10 -> 254
A11: 11 | B11: 0.44 | K11: 9 | L11: 140 | M11: =0.2*伤害计算器!B5+L11 -> 264
A12: 12 | B12: 0.48 | K12: 10 | L12: 150 | M12: =0.2*伤害计算器!B5+L12 -> 274
A13: 13 | B13: 0.52 | K13: 11 | L13: 160 | M13: =0.2*伤害计算器!B5+L13 -> 284
A14: 14 | B14: 0.56 | K14: 12 | L14: 170 | M14: =0.2*伤害计算器!B5+L14 -> 294
A15: 15 | B15: 0.6 | K15: 13 | L15: 180 | M15: =0.2*伤害计算器!B5+L15 -> 304
A16: 16 | B16: 0.64 | K16: 14 | L16: 190 | M16: =0.2*伤害计算器!B5+L16 -> 314
A17: 17 | B17: 0.68 | K17: 15 | L17: 200 | M17: =0.2*伤害计算器!B5+L17 -> 324
A18: 18 | B18: 0.72 | K18: 16 | L18: 210 | M18: =0.2*伤害计算器!B5+L18 -> 334
A19: 19 | B19: 0.76 | K19: 17 | L19: 220 | M19: =0.2*伤害计算器!B5+L19 -> 344
A20: 20 | B20: 0.8 | K20: 18 | L20: 230 | M20: =0.2*伤害计算器!B5+L20 -> 354
K21: 19 | L21: 240 | M21: =0.2*伤害计算器!B5+L21 -> 364
K22: 20 | L22: 250 | M22: =0.2*伤害计算器!B5+L22 -> 374

Sheet 备注
A1: 原来这个爆发力的额外伤害是吃一遍防御乘区然后再跟技能伤害加算
A2: 爆发力追伤=(技能基础+法强)*爆发力系数*防御修正
A3: 天赋和叠层还没做计算器……
